Workbook

Sheet List Ticket
A1: Deposit = 1 Tiket/hari | Streak 5 Hari = +5 Bonus | Streak 10 Hari = +20 Bonus
A2: MEMBER | C2: 46203 | D2: =C2+1 | E2: =D2+1 | F2: =E2+1 | G2: =F2+3 | H2: =G2+1 | I2: =H2+1 | J2: =I2+1 | K2: =J2+1 | L2: =K2+3 | M2: =L2+1 | N2: =M2+1 | O2: =N2+1 | P2: =O2+1 | Q2: =P2+3 | R2: =Q2+1 | S2: =R2+1 | T2: =S2+1 | U2: =T2+1 | V2: =U2+3 | W2: =V2+1 | X2: =W2+1 | Y2: =X2+1 | Z2: =Y2+1 | AA2: Total Tiket | AB2: Streak (manual) | AC2: x5 Streak Bonus | AD2: x10 Streak Bonus | AE2: Total Bonus
C3: Sel | D3: Rab | E3: Kamis | F3: Jum | G3: Sen | H3: Sel | I3: Rab | J3: Kamis | K3: Jum | L3: Sen | M3: Sel | N3: Rab | O3: Kamis | P3: Jum | Q3: Sen | R3: Sel | S3: Rab | T3: Kamis | U3: Jum | V3: Sen | W3: Sel | X3: Rab | Y3: Kamis | Z3: Jum
B4: TOTAL | C4: =SUM(C5:C1105) | D4: =SUM(D5:D1105) | E4: =SUM(E5:E1105) | F4: =SUM(F5:F1105) | G4: =SUM(G5:G1105) | H4: =SUM(H5:H1105) | I4: =SUM(I5:I1105) | J4: =SUM(J5:J1105) | ... AE4: =SUM(AE5:AE1105)
A5: 1 | B5: yuli | C5: 1 | D5: 1 | E5: 1 | F5: 1 | G5: 1 | H5: 1 | I5: 1 | J5: 1 | K5: 1 | L5: 1 | M5: 1 | N5: 1 | O5: 1 | P5: 1 | Q5: 1 | R5: 1 | S5: 1 | T5: 1 | U5: 1 | V5: 0 | W5: 0 | X5: 0 | Y5: 0 | Z5: 0 | AA5: =(SUM(C5:Y5))+AE5 | AB5: 0 | AC5: =MIN(3, SUMPRODUCT((MOD('Streak'!C5:Y5,5)=0)*(MOD('Streak'!C5:Y5,10)<>0)*('Streak'!C5:Y5>0))) * 5 | AD5: =MIN(2, SUMPRODUCT((MOD('Streak'!C5:Y5,10)=0)*('Streak'!C5:Y5>0))) * 20 | AE5: =SUM(AC5:AD5)
A6: =A5+1 | B6: ganda | C6: 1 | D6: 0 | E6: 0 | F6: 0 | G6: 0 | H6: 0 | I6: 0 | J6: 0 | K6: 0 | L6: 0 | M6: 0 | N6: 0 | O6: 0 | P6: 0 | Q6: 1 | R6: 0 | S6: 0 | T6: 0 | U6: 0 | V6: 1 | W6: 0 | X6: 0 | Y6: 0 | Z6: 0 | AA6: =(SUM(C6:Y6))+AE6 | AB6: 0 | AC6: =MIN(3, SUMPRODUCT((MOD('Streak'!C6:Y6,5)=0)*(MOD('Streak'!C6:Y6,10)<>0)*('Streak'!C6:Y6>0))) * 5 | AD6: =MIN(2, SUMPRODUCT((MOD('Streak'!C6:Y6,10)=0)*('Streak'!C6:Y6>0))) * 20 | AE6: =SUM(AC6:AD6)
A7: =A6+1 | B7: KKyLsQiu | C7: 1 | D7: 1 | E7: 0 | F7: 1 | G7: 0 | H7: 0 | I7: 1 | J7: 0 | K7: 1 | L7: 1 | M7: 1 | N7: 1 | O7: 1 | P7: 1 | Q7: 1 | R7: 1 | S7: 1 | T7: 1 | U7: 1 | V7: 1 | W7: 0 | X7: 0 | Y7: 0 | Z7: 0 | AA7: =(SUM(C7:Y7))+AE7 | AB7: 0 | AC7: =MIN(3, SUMPRODUCT((MOD('Streak'!C7:Y7,5)=0)*(MOD('Streak'!C7:Y7,10)<>0)*('Streak'!C7:Y7>0))) * 5 | AD7: =MIN(2, SUMPRODUCT((MOD('Streak'!C7:Y7,10)=0)*('Streak'!C7:Y7>0))) * 20 | AE7: =SUM(AC7:AD7)
A8: =A7+1 | B8: Toyib | C8: 1 | D8: 0 | E8: 0 | F8: 0 | G8: 0 | H8: 0 | I8: 0 | J8: 0 | K8: 1 | L8: 0 | M8: 0 | N8: 0 | O8: 0 | P8: 1 | Q8: 1 | R8: 1 | S8: 1 | T8: 1 | U8: 1 | V8: 0 | W8: 0 | X8: 0 | Y8: 0 | Z8: 0 | AA8: =(SUM(C8:Y8))+AE8 | AB8: 0 | AC8: =MIN(3, SUMPRODUCT((MOD('Streak'!C8:Y8,5)=0)*(MOD('Streak'!C8:Y8,10)<>0)*('Streak'!C8:Y8>0))) * 5 | AD8: =MIN(2, SUMPRODUCT((MOD('Streak'!C8:Y8,10)=0)*('Streak'!C8:Y8>0))) * 20 | AE8: =SUM(AC8:AD8)
A9: =A8+1 | B9: Irvin_1548314 | C9: 1 | D9: 0 | E9: 1 | F9: 1 | G9: 1 | H9: 1 | I9: 1 | J9: 1 | K9: 1 | L9: 0 | M9: 0 | N9: 1 | O9: 0 | P9: 1 | Q9: 1 | R9: 1 | S9: 1 | T9: 1 | U9: 1 | V9: 1 | W9: 0 | X9: 0 | Y9: 0 | Z9: 0 | AA9: =(SUM(C9:Y9))+AE9 | AB9: 0 | AC9: =MIN(3, SUMPRODUCT((MOD('Streak'!C9:Y9,5)=0)*(MOD('Streak'!C9:Y9,10)<>0)*('Streak'!C9:Y9>0))) * 5 | AD9: =MIN(2, SUMPRODUCT((MOD('Streak'!C9:Y9,10)=0)*('Streak'!C9:Y9>0))) * 20 | AE9: =SUM(AC9:AD9)
A10: =A9+1 | B10: Cuan XRP | C10: 1 | D10: 1 | E10: 1 | F10: 1 | G10: 1 | H10: 1 | I10: 1 | J10: 0 | K10: 0 | L10: 0 | M10: 0 | N10: 0 | O10: 0 | P10: 1 | Q10: 1 | R10: 0 | S10: 0 | T10: 0 | U10: 0 | V10: 0 | W10: 0 | X10: 0 | Y10: 0 | Z10: 0 | AA10: =(SUM(C10:Y10))+AE10 | AB10: 0 | AC10: =MIN(3, SUMPRODUCT((MOD('Streak'!C10:Y10,5)=0)*(MOD('Streak'!C10:Y10,10)<>0)*('Streak'!C10:Y10>0))) * 5 | AD10: =MIN(2, SUMPRODUCT((MOD('Streak'!C10:Y10,10)=0)*('Streak'!C10:Y10>0))) * 20 | AE10: =SUM(AC10:AD10)
A11: =A10+1 | B11: Scucum | C11: 1 | D11: 1 | E11: 1 | F11: 1 | G11: 0 | H11: 1 | I11: 0 | J11: 0 | K11: 1 | L11: 0 | M11: 0 | N11: 1 | O11: 0 | P11: 1 | Q11: 0 | R11: 0 | S11: 1 | T11: 0 | U11: 0 | V11: 0 | W11: 0 | X11: 0 | Y11: 0 | Z11: 0 | AA11: =(SUM(C11:Y11))+AE11 | AB11: 0 | AC11: =MIN(3, SUMPRODUCT((MOD('Streak'!C11:Y11,5)=0)*(MOD('Streak'!C11:Y11,10)<>0)*('Streak'!C11:Y11>0))) * 5 | AD11: =MIN(2, SUMPRODUCT((MOD('Streak'!C11:Y11,10)=0)*('Streak'!C11:Y11>0))) * 20 | AE11: =SUM(AC11:AD11)
A12: =A11+1 | B12: ShinTaeOng | C12: 1 | D12: 0 | E12: 0 | F12: 1 | G12: 1 | H12: 0 | I12: 0 | J12: 1 | K12: 0 | L12: 0 | M12: 0 | N12: 0 | O12: 0 | P12: 0 | Q12: 0 | R12: 0 | S12: 0 | T12: 0 | U12: 0 | V12: 0 | W12: 0 | X12: 0 | Y12: 0 | Z12: 0 | AA12: =(SUM(C12:Y12))+AE12 | AB12: 0 | AC12: =MIN(3, SUMPRODUCT((MOD('Streak'!C12:Y12,5)=0)*(MOD('Streak'!C12:Y12,10)<>0)*('Streak'!C12:Y12>0))) * 5 | AD12: =MIN(2, SUMPRODUCT((MOD('Streak'!C12:Y12,10)=0)*('Streak'!C12:Y12>0))) * 20 | AE12: =SUM(AC12:AD12)
A13: =A12+1 | B13: Caniago | C13: 1 | D13: 0 | E13: 1 | F13: 1 | G13: 0 | H13: 0 | I13: 0 | J13: 1 | K13: 0 | L13: 0 | M13: 1 | N13: 0 | O13: 0 | P13: 0 | Q13: 1 | R13: 0 | S13: 1 | T13: 1 | U13: 0 | V13: 0 | W13: 0 | X13: 0 | Y13: 0 | Z13: 0 | AA13: =(SUM(C13:Y13))+AE13 | AB13: 0 | AC13: =MIN(3, SUMPRODUCT((MOD('Streak'!C13:Y13,5)=0)*(MOD('Streak'!C13:Y13,10)<>0)*('Streak'!C13:Y13>0))) * 5 | AD13: =MIN(2, SUMPRODUCT((MOD('Streak'!C13:Y13,10)=0)*('Streak'!C13:Y13>0))) * 20 | AE13: =SUM(AC13:AD13)
A14: =A13+1 | B14: Zuna76 | C14: 1 | D14: 0 | E14: 1 | F14: 0 | G14: 0 | H14: 1 | I14: 0 | J14: 1 | K14: 0 | L14: 0 | M14: 0 | N14: 0 | O14: 0 | P14: 0 | Q14: 0 | R14: 0 | S14: 0 | T14: 0 | U14: 0 | V14: 0 | W14: 0 | X14: 0 | Y14: 0 | Z14: 0 | AA14: =(SUM(C14:Y14))+AE14 | AB14: 0 | AC14: =MIN(3, SUMPRODUCT((MOD('Streak'!C14:Y14,5)=0)*(MOD('Streak'!C14:Y14,10)<>0)*('Streak'!C14:Y14>0))) * 5 | AD14: =MIN(2, SUMPRODUCT((MOD('Streak'!C14:Y14,10)=0)*('Streak'!C14:Y14>0))) * 20 | AE14: =SUM(AC14:AD14)
A15: =A14+1 | B15: Marpu'ah | C15: 1 | D15: 0 | E15: 0 | F15: 1 | G15: 0 | H15: 0 | I15: 1 | J15: 0 | K15: 0 | L15: 0 | M15: 0 | N15: 0 | O15: 0 | P15: 0 | Q15: 1 | R15: 1 | S15: 0 | T15: 0 | U15: 0 | V15: 1 | W15: 0 | X15: 0 | Y15: 0 | Z15: 0 | AA15: =(SUM(C15:Y15))+AE15 | AB15: 0 | AC15: =MIN(3, SUMPRODUCT((MOD('Streak'!C15:Y15,5)=0)*(MOD('Streak'!C15:Y15,10)<>0)*('Streak'!C15:Y15>0))) * 5 | AD15: =MIN(2, SUMPRODUCT((MOD('Streak'!C15:Y15,10)=0)*('Streak'!C15:Y15>0))) * 20 | AE15: =SUM(AC15:AD15)
A16: =A15+1 | B16: Mohamadtanuri37 | C16: 1 | D16: 0 | E16: 1 | F16: 1 | G16: 0 | H16: 0 | I16: 1 | J16: 0 | K16: 1 | L16: 1 | M16: 0 | N16: 0 | O16: 0 | P16: 0 | Q16: 1 | R16: 0 | S16: 0 | T16: 0 | U16: 1 | V16: 0 | W16: 0 | X16: 0 | Y16: 0 | Z16: 0 | AA16: =(SUM(C16:Y16))+AE16 | AB16: 0 | AC16: =MIN(3, SUMPRODUCT((MOD('Streak'!C16:Y16,5)=0)*(MOD('Streak'!C16:Y16,10)<>0)*('Streak'!C16:Y16>0))) * 5 | AD16: =MIN(2, SUMPRODUCT((MOD('Streak'!C16:Y16,10)=0)*('Streak'!C16:Y16>0))) * 20 | AE16: =SUM(AC16:AD16)
A17: =A16+1 | B17: FZfxAroHAga | C17: 1 | D17: 0 | E17: 0 | F17: 0 | G17: 0 | H17: 0 | I17: 0 | J17: 0 | K17: 0 | L17: 0 | M17: 0 | N17: 0 | O17: 0 | P17: 0 | Q17: 0 | R17: 0 | S17: 0 | T17: 0 | U17: 0 | V17: 0 | W17: 0 | X17: 0 | Y17: 0 | Z17: 0 | AA17: =(SUM(C17:Y17))+AE17 | AB17: 0 | AC17: =MIN(3, SUMPRODUCT((MOD('Streak'!C17:Y17,5)=0)*(MOD('Streak'!C17:Y17,10)<>0)*('Streak'!C17:Y17>0))) * 5 | AD17: =MIN(2, SUMPRODUCT((MOD('Streak'!C17:Y17,10)=0)*('Streak'!C17:Y17>0))) * 20 | AE17: =SUM(AC17:AD17)
... A132: =A131+1 | B132: Diandra | C132: 0 | D132: 0 | E132: 0 | F132: 0 | G132: 0 | H132: 0 | I132: 0 | J132: 0 | K132: 0 | L132: 0 | M132: 0 | N132: 0 | O132: 0 | P132: 0 | Q132: 0 | R132: 0 | S132: 0 | T132: 0 | U132: 0 | V132: 1 | W132: 0 | X132: 0 | Y132: 0 | Z132: 0 | AA132: =(SUM(C132:Y132))+AE132 | AB132: 0 | AC132: =MIN(3, SUMPRODUCT((MOD('Streak'!C132:Y132,5)=0)*(MOD('Streak'!C132:Y132,10)<>0)*('Streak'!C132:Y132>0))) * 5 | AD132: =MIN(2, SUMPRODUCT((MOD('Streak'!C132:Y132,10)=0)*('Streak'!C132:Y132>0))) * 20 | AE132: =SUM(AC132:AD132)
A133: =A132+1 | C133: 0 | D133: 0 | E133: 0 | F133: 0 | G133: 0 | H133: 0 | I133: 0 | J133: 0 | K133: 0 | L133: 0 | M133: 0 | N133: 0 | O133: 0 | P133: 0 | Q133: 0 | R133: 0 | S133: 0 | T133: 0 | U133: 0 | V133: 0 | W133: 0 | X133: 0 | Y133: 0 | Z133: 0 | AA133: =(SUM(C133:Y133))+AE133 | AB133: 0 | AC133: =MIN(3, SUMPRODUCT((MOD('Streak'!C133:Y133,5)=0)*(MOD('Streak'!C133:Y133,10)<>0)*('Streak'!C133:Y133>0))) * 5 | AD133: =MIN(2, SUMPRODUCT((MOD('Streak'!C133:Y133,10)=0)*('Streak'!C133:Y133>0))) * 20 | AE133: =SUM(AC133:AD133)
A134: =A133+1 | C134: 0 | D134: 0 | E134: 0 | F134: 0 | G134: 0 | H134: 0 | I134: 0 | J134: 0 | K134: 0 | L134: 0 | M134: 0 | N134: 0 | O134: 0 | P134: 0 | Q134: 0 | R134: 0 | S134: 0 | T134: 0 | U134: 0 | V134: 0 | W134: 0 | X134: 0 | Y134: 0 | Z134: 0 | AA134: =(SUM(C134:Y134))+AE134 | AB134: 0 | AC134: =MIN(3, SUMPRODUCT((MOD('Streak'!C134:Y134,5)=0)*(MOD('Streak'!C134:Y134,10)<>0)*('Streak'!C134:Y134>0))) * 5 | AD134: =MIN(2, SUMPRODUCT((MOD('Streak'!C134:Y134,10)=0)*('Streak'!C134:Y134>0))) * 20 | AE134: =SUM(AC134:AD134)
A135: =A134+1 | C135: 0 | D135: 0 | E135: 0 | F135: 0 | G135: 0 | H135: 0 | I135: 0 | J135: 0 | K135: 0 | L135: 0 | M135: 0 | N135: 0 | O135: 0 | P135: 0 | Q135: 0 | R135: 0 | S135: 0 | T135: 0 | U135: 0 | V135: 0 | W135: 0 | X135: 0 | Y135: 0 | Z135: 0 | AA135: =(SUM(C135:Y135))+AE135 | AB135: 0 | AC135: =MIN(3, SUMPRODUCT((MOD('Streak'!C135:Y135,5)=0)*(MOD('Streak'!C135:Y135,10)<>0)*('Streak'!C135:Y135>0))) * 5 | AD135: =MIN(2, SUMPRODUCT((MOD('Streak'!C135:Y135,10)=0)*('Streak'!C135:Y135>0))) * 20 | AE135: =SUM(AC135:AD135)
A136: =A135+1 | C136: 0 | D136: 0 | E136: 0 | F136: 0 | G136: 0 | H136: 0 | I136: 0 | J136: 0 | K136: 0 | L136: 0 | M136: 0 | N136: 0 | O136: 0 | P136: 0 | Q136: 0 | R136: 0 | S136: 0 | T136: 0 | U136: 0 | V136: 0 | W136: 0 | X136: 0 | Y136: 0 | Z136: 0 | AA136: =(SUM(C136:Y136))+AE136 | AB136: 0 | AC136: =MIN(3, SUMPRODUCT((MOD('Streak'!C136:Y136,5)=0)*(MOD('Streak'!C136:Y136,10)<>0)*('Streak'!C136:Y136>0))) * 5 | AD136: =MIN(2, SUMPRODUCT((MOD('Streak'!C136:Y136,10)=0)*('Streak'!C136:Y136>0))) * 20 | AE136: =SUM(AC136:AD136)
A137: =A136+1 | C137: 0 | D137: 0 | E137: 0 | F137: 0 | G137: 0 | H137: 0 | I137: 0 | J137: 0 | K137: 0 | L137: 0 | M137: 0 | N137: 0 | O137: 0 | P137: 0 | Q137: 0 | R137: 0 | S137: 0 | T137: 0 | U137: 0 | V137: 0 | W137: 0 | X137: 0 | Y137: 0 | Z137: 0 | AA137: =(SUM(C137:Y137))+AE137 | AB137: 0 | AC137: =MIN(3, SUMPRODUCT((MOD('Streak'!C137:Y137,5)=0)*(MOD('Streak'!C137:Y137,10)<>0)*('Streak'!C137:Y137>0))) * 5 | AD137: =MIN(2, SUMPRODUCT((MOD('Streak'!C137:Y137,10)=0)*('Streak'!C137:Y137>0))) * 20 | AE137: =SUM(AC137:AD137)
A138: =A137+1 | C138: 0 | D138: 0 | E138: 0 | F138: 0 | G138: 0 | H138: 0 | I138: 0 | J138: 0 | K138: 0 | L138: 0 | M138: 0 | N138: 0 | O138: 0 | P138: 0 | Q138: 0 | R138: 0 | S138: 0 | T138: 0 | U138: 0 | V138: 0 | W138: 0 | X138: 0 | Y138: 0 | Z138: 0 | AA138: =(SUM(C138:Y138))+AE138 | AB138: 0 | AC138: =MIN(3, SUMPRODUCT((MOD('Streak'!C138:Y138,5)=0)*(MOD('Streak'!C138:Y138,10)<>0)*('Streak'!C138:Y138>0))) * 5 | AD138: =MIN(2, SUMPRODUCT((MOD('Streak'!C138:Y138,10)=0)*('Streak'!C138:Y138>0))) * 20 | AE138: =SUM(AC138:AD138)
A139: =A138+1 | C139: 0 | D139: 0 | E139: 0 | F139: 0 | G139: 0 | H139: 0 | I139: 0 | J139: 0 | K139: 0 | L139: 0 | M139: 0 | N139: 0 | O139: 0 | P139: 0 | Q139: 0 | R139: 0 | S139: 0 | T139: 0 | U139: 0 | V139: 0 | W139: 0 | X139: 0 | Y139: 0 | Z139: 0 | AA139: =(SUM(C139:Y139))+AE139 | AB139: 0 | AC139: =MIN(3, SUMPRODUCT((MOD('Streak'!C139:Y139,5)=0)*(MOD('Streak'!C139:Y139,10)<>0)*('Streak'!C139:Y139>0))) * 5 | AD139: =MIN(2, SUMPRODUCT((MOD('Streak'!C139:Y139,10)=0)*('Streak'!C139:Y139>0))) * 20 | AE139: =SUM(AC139:AD139)
A140: =A139+1 | C140: 0 | D140: 0 | E140: 0 | F140: 0 | G140: 0 | H140: 0 | I140: 0 | J140: 0 | K140: 0 | L140: 0 | M140: 0 | N140: 0 | O140: 0 | P140: 0 | Q140: 0 | R140: 0 | S140: 0 | T140: 0 | U140: 0 | V140: 0 | W140: 0 | X140: 0 | Y140: 0 | Z140: 0 | AA140: =(SUM(C140:Y140))+AE140 | AB140: 0 | AC140: =MIN(3, SUMPRODUCT((MOD('Streak'!C140:Y140,5)=0)*(MOD('Streak'!C140:Y140,10)<>0)*('Streak'!C140:Y140>0))) * 5 | AD140: =MIN(2, SUMPRODUCT((MOD('Streak'!C140:Y140,10)=0)*('Streak'!C140:Y140>0))) * 20 | AE140: =SUM(AC140:AD140)
A141: =A140+1 | C141: 0 | D141: 0 | E141: 0 | F141: 0 | G141: 0 | H141: 0 | I141: 0 | J141: 0 | K141: 0 | L141: 0 | M141: 0 | N141: 0 | O141: 0 | P141: 0 | Q141: 0 | R141: 0 | S141: 0 | T141: 0 | U141: 0 | V141: 0 | W141: 0 | X141: 0 | Y141: 0 | Z141: 0 | AA141: =(SUM(C141:Y141))+AE141 | AB141: 0 | AC141: =MIN(3, SUMPRODUCT((MOD('Streak'!C141:Y141,5)=0)*(MOD('Streak'!C141:Y141,10)<>0)*('Streak'!C141:Y141>0))) * 5 | AD141: =MIN(2, SUMPRODUCT((MOD('Streak'!C141:Y141,10)=0)*('Streak'!C141:Y141>0))) * 20 | AE141: =SUM(AC141:AD141)
A142: =A141+1 | C142: 0 | D142: 0 | E142: 0 | F142: 0 | G142: 0 | H142: 0 | I142: 0 | J142: 0 | K142: 0 | L142: 0 | M142: 0 | N142: 0 | O142: 0 | P142: 0 | Q142: 0 | R142: 0 | S142: 0 | T142: 0 | U142: 0 | V142: 0 | W142: 0 | X142: 0 | Y142: 0 | Z142: 0 | AA142: =(SUM(C142:Y142))+AE142 | AB142: 0 | AC142: =MIN(3, SUMPRODUCT((MOD('Streak'!C142:Y142,5)=0)*(MOD('Streak'!C142:Y142,10)<>0)*('Streak'!C142:Y142>0))) * 5 | AD142: =MIN(2, SUMPRODUCT((MOD('Streak'!C142:Y142,10)=0)*('Streak'!C142:Y142>0))) * 20 | AE142: =SUM(AC142:AD142)
A143: =A142+1 | C143: 0 | D143: 0 | E143: 0 | F143: 0 | G143: 0 | H143: 0 | I143: 0 | J143: 0 | K143: 0 | L143: 0 | M143: 0 | N143: 0 | O143: 0 | P143: 0 | Q143: 0 | R143: 0 | S143: 0 | T143: 0 | U143: 0 | V143: 0 | W143: 0 | X143: 0 | Y143: 0 | Z143: 0 | AA143: =(SUM(C143:Y143))+AE143 | AB143: 0 | AC143: =MIN(3, SUMPRODUCT((MOD('Streak'!C143:Y143,5)=0)*(MOD('Streak'!C143:Y143,10)<>0)*('Streak'!C143:Y143>0))) * 5 | AD143: =MIN(2, SUMPRODUCT((MOD('Streak'!C143:Y143,10)=0)*('Streak'!C143:Y143>0))) * 20 | AE143: =SUM(AC143:AD143)
A144: =A143+1 | C144: 0 | D144: 0 | E144: 0 | F144: 0 | G144: 0 | H144: 0 | I144: 0 | J144: 0 | K144: 0 | L144: 0 | M144: 0 | N144: 0 | O144: 0 | P144: 0 | Q144: 0 | R144: 0 | S144: 0 | T144: 0 | U144: 0 | V144: 0 | W144: 0 | X144: 0 | Y144: 0 | Z144: 0 | AA144: =(SUM(C144:Y144))+AE144 | AB144: 0 | AC144: =MIN(3, SUMPRODUCT((MOD('Streak'!C144:Y144,5)=0)*(MOD('Streak'!C144:Y144,10)<>0)*('Streak'!C144:Y144>0))) * 5 | AD144: =MIN(2, SUMPRODUCT((MOD('Streak'!C144:Y144,10)=0)*('Streak'!C144:Y144>0))) * 20 | AE144: =SUM(AC144:AD144)
... A218: =A217+1 | C218: 0 | D218: 0 | E218: 0 | F218: 0 | G218: 0 | H218: 0 | I218: 0 | J218: 0 | K218: 0 | L218: 0 | M218: 0 | N218: 0 | O218: 0 | P218: 0 | Q218: 0 | R218: 0 | S218: 0 | T218: 0 | U218: 0 | V218: 0 | W218: 0 | X218: 0 | Y218: 0 | Z218: 0 | AA218: =(SUM(C218:Y218))+AE218 | AB218: 0 | AC218: =MIN(3, SUMPRODUCT((MOD('Streak'!C218:Y218,5)=0)*(MOD('Streak'!C218:Y218,10)<>0)*('Streak'!C218:Y218>0))) * 5 | AD218: =MIN(2, SUMPRODUCT((MOD('Streak'!C218:Y218,10)=0)*('Streak'!C218:Y218>0))) * 20 | AE218: =SUM(AC218:AD218)
A219: =A218+1
A220: =A219+1
A221: =A220+1
A222: =A221+1
A223: =A222+1
A224: =A223+1
A225: =A224+1
A226: =A225+1
A227: =A226+1
...

Sheet Streak
A1: Deposit = 1 Tiket/hari | Streak 5 Hari = +5 Bonus | Streak 10 Hari = +20 Bonus
A2: MEMBER | C2: ='List Ticket'!C2 | D2: ='List Ticket'!D2 | E2: ='List Ticket'!E2 | F2: ='List Ticket'!F2 | G2: ='List Ticket'!G2 | H2: ='List Ticket'!H2 | I2: ='List Ticket'!I2 | J2: ='List Ticket'!J2 | ... Z2: ='List Ticket'!Z2 | AA2: Streaks
C3: ='List Ticket'!C3 | D3: ='List Ticket'!D3 | E3: ='List Ticket'!E3 | F3: ='List Ticket'!F3 | G3: ='List Ticket'!G3 | H3: ='List Ticket'!H3 | I3: ='List Ticket'!I3 | J3: ='List Ticket'!J3 | ... Z3: ='List Ticket'!Z3
B4: TOTAL | C4: =SUM(C5:C1105) | D4: =SUM(D5:D1105) | E4: =SUM(E5:E1105) | F4: =SUM(F5:F1105) | G4: =SUM(G5:G1105) | H4: =SUM(H5:H1105) | I4: =SUM(I5:I1105) | J4: =SUM(J5:J1105) | ... AA4: =SUM(AA5:AA1105)
A5: ='List Ticket'!A5 | B5: ='List Ticket'!B5 | C5: =IF('List Ticket'!C5=1, 1, 0) | D5: =IF('List Ticket'!D5=1, C5+1, 0) | E5: =IF('List Ticket'!E5=1, D5+1, 0) | F5: =IF('List Ticket'!F5=1, E5+1, 0) | G5: =IF('List Ticket'!G5=1, F5+1, 0) | H5: =IF('List Ticket'!H5=1, G5+1, 0) | I5: =IF('List Ticket'!I5=1, H5+1, 0) | J5: =IF('List Ticket'!J5=1, I5+1, 0) | K5: =IF('List Ticket'!K5=1, J5+1, 0) | ... Z5: =IF('List Ticket'!Z5=1, Y5+1, 0) | AA5: =SUM(C5:Y5)
A6: ='List Ticket'!A6 | B6: ='List Ticket'!B6 | C6: =IF('List Ticket'!C6=1, 1, 0) | D6: =IF('List Ticket'!D6=1, C6+1, 0) | E6: =IF('List Ticket'!E6=1, D6+1, 0) | F6: =IF('List Ticket'!F6=1, E6+1, 0) | G6: =IF('List Ticket'!G6=1, F6+1, 0) | H6: =IF('List Ticket'!H6=1, G6+1, 0) | I6: =IF('List Ticket'!I6=1, H6+1, 0) | J6: =IF('List Ticket'!J6=1, I6+1, 0) | K6: =IF('List Ticket'!K6=1, J6+1, 0) | ... Z6: =IF('List Ticket'!Z6=1, Y6+1, 0) | AA6: =SUM(C6:Y6)
A7: ='List Ticket'!A7 | B7: ='List Ticket'!B7 | C7: =IF('List Ticket'!C7=1, 1, 0) | D7: =IF('List Ticket'!D7=1, C7+1, 0) | E7: =IF('List Ticket'!E7=1, D7+1, 0) | F7: =IF('List Ticket'!F7=1, E7+1, 0) | G7: =IF('List Ticket'!G7=1, F7+1, 0) | H7: =IF('List Ticket'!H7=1, G7+1, 0) | I7: =IF('List Ticket'!I7=1, H7+1, 0) | J7: =IF('List Ticket'!J7=1, I7+1, 0) | K7: =IF('List Ticket'!K7=1, J7+1, 0) | ... Z7: =IF('List Ticket'!Z7=1, Y7+1, 0) | AA7: =SUM(C7:Y7)
A8: ='List Ticket'!A8 | B8: ='List Ticket'!B8 | C8: =IF('List Ticket'!C8=1, 1, 0) | D8: =IF('List Ticket'!D8=1, C8+1, 0) | E8: =IF('List Ticket'!E8=1, D8+1, 0) | F8: =IF('List Ticket'!F8=1, E8+1, 0) | G8: =IF('List Ticket'!G8=1, F8+1, 0) | H8: =IF('List Ticket'!H8=1, G8+1, 0) | I8: =IF('List Ticket'!I8=1, H8+1, 0) | J8: =IF('List Ticket'!J8=1, I8+1, 0) | K8: =IF('List Ticket'!K8=1, J8+1, 0) | ... Z8: =IF('List Ticket'!Z8=1, Y8+1, 0) | AA8: =SUM(C8:Y8)
A9: ='List Ticket'!A9 | B9: ='List Ticket'!B9 | C9: =IF('List Ticket'!C9=1, 1, 0) | D9: =IF('List Ticket'!D9=1, C9+1, 0) | E9: =IF('List Ticket'!E9=1, D9+1, 0) | F9: =IF('List Ticket'!F9=1, E9+1, 0) | G9: =IF('List Ticket'!G9=1, F9+1, 0) | H9: =IF('List Ticket'!H9=1, G9+1, 0) | I9: =IF('List Ticket'!I9=1, H9+1, 0) | J9: =IF('List Ticket'!J9=1, I9+1, 0) | K9: =IF('List Ticket'!K9=1, J9+1, 0) | ... Z9: =IF('List Ticket'!Z9=1, Y9+1, 0) | AA9: =SUM(C9:Y9)
A10: ='List Ticket'!A10 | B10: ='List Ticket'!B10 | C10: =IF('List Ticket'!C10=1, 1, 0) | D10: =IF('List Ticket'!D10=1, C10+1, 0) | E10: =IF('List Ticket'!E10=1, D10+1, 0) | F10: =IF('List Ticket'!F10=1, E10+1, 0) | G10: =IF('List Ticket'!G10=1, F10+1, 0) | H10: =IF('List Ticket'!H10=1, G10+1, 0) | I10: =IF('List Ticket'!I10=1, H10+1, 0) | J10: =IF('List Ticket'!J10=1, I10+1, 0) | K10: =IF('List Ticket'!K10=1, J10+1, 0) | ... Z10: =IF('List Ticket'!Z10=1, Y10+1, 0) | AA10: =SUM(C10:Y10)
A11: ='List Ticket'!A11 | B11: ='List Ticket'!B11 | C11: =IF('List Ticket'!C11=1, 1, 0) | D11: =IF('List Ticket'!D11=1, C11+1, 0) | E11: =IF('List Ticket'!E11=1, D11+1, 0) | F11: =IF('List Ticket'!F11=1, E11+1, 0) | G11: =IF('List Ticket'!G11=1, F11+1, 0) | H11: =IF('List Ticket'!H11=1, G11+1, 0) | I11: =IF('List Ticket'!I11=1, H11+1, 0) | J11: =IF('List Ticket'!J11=1, I11+1, 0) | K11: =IF('List Ticket'!K11=1, J11+1, 0) | ... Z11: =IF('List Ticket'!Z11=1, Y11+1, 0) | AA11: =SUM(C11:Y11)
A12: ='List Ticket'!A12 | B12: ='List Ticket'!B12 | C12: =IF('List Ticket'!C12=1, 1, 0) | D12: =IF('List Ticket'!D12=1, C12+1, 0) | E12: =IF('List Ticket'!E12=1, D12+1, 0) | F12: =IF('List Ticket'!F12=1, E12+1, 0) | G12: =IF('List Ticket'!G12=1, F12+1, 0) | H12: =IF('List Ticket'!H12=1, G12+1, 0) | I12: =IF('List Ticket'!I12=1, H12+1, 0) | J12: =IF('List Ticket'!J12=1, I12+1, 0) | K12: =IF('List Ticket'!K12=1, J12+1, 0) | ... Z12: =IF('List Ticket'!Z12=1, Y12+1, 0) | AA12: =SUM(C12:Y12)
A13: ='List Ticket'!A13 | B13: ='List Ticket'!B13 | C13: =IF('List Ticket'!C13=1, 1, 0) | D13: =IF('List Ticket'!D13=1, C13+1, 0) | E13: =IF('List Ticket'!E13=1, D13+1, 0) | F13: =IF('List Ticket'!F13=1, E13+1, 0) | G13: =IF('List Ticket'!G13=1, F13+1, 0) | H13: =IF('List Ticket'!H13=1, G13+1, 0) | I13: =IF('List Ticket'!I13=1, H13+1, 0) | J13: =IF('List Ticket'!J13=1, I13+1, 0) | K13: =IF('List Ticket'!K13=1, J13+1, 0) | ... Z13: =IF('List Ticket'!Z13=1, Y13+1, 0) | AA13: =SUM(C13:Y13)
A14: ='List Ticket'!A14 | B14: ='List Ticket'!B14 | C14: =IF('List Ticket'!C14=1, 1, 0) | D14: =IF('List Ticket'!D14=1, C14+1, 0) | E14: =IF('List Ticket'!E14=1, D14+1, 0) | F14: =IF('List Ticket'!F14=1, E14+1, 0) | G14: =IF('List Ticket'!G14=1, F14+1, 0) | H14: =IF('List Ticket'!H14=1, G14+1, 0) | I14: =IF('List Ticket'!I14=1, H14+1, 0) | J14: =IF('List Ticket'!J14=1, I14+1, 0) | K14: =IF('List Ticket'!K14=1, J14+1, 0) | ... Z14: =IF('List Ticket'!Z14=1, Y14+1, 0) | AA14: =SUM(C14:Y14)
A15: ='List Ticket'!A15 | B15: ='List Ticket'!B15 | C15: =IF('List Ticket'!C15=1, 1, 0) | D15: =IF('List Ticket'!D15=1, C15+1, 0) | E15: =IF('List Ticket'!E15=1, D15+1, 0) | F15: =IF('List Ticket'!F15=1, E15+1, 0) | G15: =IF('List Ticket'!G15=1, F15+1, 0) | H15: =IF('List Ticket'!H15=1, G15+1, 0) | I15: =IF('List Ticket'!I15=1, H15+1, 0) | J15: =IF('List Ticket'!J15=1, I15+1, 0) | K15: =IF('List Ticket'!K15=1, J15+1, 0) | ... Z15: =IF('List Ticket'!Z15=1, Y15+1, 0) | AA15: =SUM(C15:Y15)
A16: ='List Ticket'!A16 | B16: ='List Ticket'!B16 | C16: =IF('List Ticket'!C16=1, 1, 0) | D16: =IF('List Ticket'!D16=1, C16+1, 0) | E16: =IF('List Ticket'!E16=1, D16+1, 0) | F16: =IF('List Ticket'!F16=1, E16+1, 0) | G16: =IF('List Ticket'!G16=1, F16+1, 0) | H16: =IF('List Ticket'!H16=1, G16+1, 0) | I16: =IF('List Ticket'!I16=1, H16+1, 0) | J16: =IF('List Ticket'!J16=1, I16+1, 0) | K16: =IF('List Ticket'!K16=1, J16+1, 0) | ... Z16: =IF('List Ticket'!Z16=1, Y16+1, 0) | AA16: =SUM(C16:Y16)
... A1025: ='List Ticket'!A1025 | B1025: ='List Ticket'!B1025 | C1025: =IF('List Ticket'!C1025=1, 1, 0) | D1025: =IF('List Ticket'!D1025=1, C1025+1, 0) | E1025: =IF('List Ticket'!E1025=1, D1025+1, 0) | F1025: =IF('List Ticket'!F1025=1, E1025+1, 0) | G1025: =IF('List Ticket'!G1025=1, F1025+1, 0) | H1025: =IF('List Ticket'!H1025=1, G1025+1, 0) | I1025: =IF('List Ticket'!I1025=1, H1025+1, 0) | J1025: =IF('List Ticket'!J1025=1, I1025+1, 0) | K1025: =IF('List Ticket'!K1025=1, J1025+1, 0) | ... Z1025: =IF('List Ticket'!Z1025=1, Y1025+1, 0) | AA1025: =SUM(C1025:Y1025)
